<?xml version="1.0"?>
<robot xmlns:xacro="http://ros.org/wiki/xacro">

  <xacro:macro name="standard_jaws"
               params="parent prefix mimic_joint">

    <!-- links -->
    <link name="${prefix}rs1_130_link">
      <visual>
        <geometry>
          <mesh filename="file://$(find reach_description)/meshes/alpha_5/end_effectors/RS1-130.dae" />
        </geometry>
        <origin xyz="0 0 0"
                rpy="0 0 0" />
      </visual>
      <collision>
        <geometry>
          <box size="0.012 0.03 0.09" />
        </geometry>
        <origin xyz="0.0 -0.008 0.045"
                rpy="0 0 0" />
      </collision>
      <inertial>
        <mass value="0.055" />
        <origin xyz="0.0 -0.008 0.045"
                rpy="0 0 0" />
        <inertia ixx="0.00004125"
                 ixy="0"
                 ixz="0"
                 iyy="0.000037785"
                 iyz="0"
                 izz="0.000004785" />
      </inertial>
    </link>

    <link name="${prefix}rs1_139_link">
      <visual>
        <geometry>
          <mesh filename="file://$(find reach_description)/meshes/alpha_5/end_effectors/RS1-139.dae" />
        </geometry>
        <origin xyz="0 0 0"
                rpy="0 0 0" />
      </visual>
      <collision>
        <geometry>
          <box size="0.012 0.03 0.09" />
        </geometry>
        <origin xyz="0.0 0.008 0.045"
                rpy="0 0 0" />
      </collision>
      <inertial>
        <mass value="0.055" />
        <origin xyz="0.0 0.008 0.045"
                rpy="0 0 0" />
        <inertia ixx="0.00004125"
                 ixy="0"
                 ixz="0"
                 iyy="0.000037785"
                 iyz="0"
                 izz="0.000004785" />
      </inertial>
    </link>

    <!-- define a tcp link for planning/control purposes -->
    <link name="${prefix}tcp">
      <inertial>
        <mass value="0.0001" />
        <inertia ixx="0.0001"
                 ixy="0"
                 ixz="0"
                 iyy="0.0001"
                 iyz="0"
                 izz="0.0001" />
      </inertial>
    </link>

    <!-- joints -->
    <joint name="${prefix}rs1_130_joint"
           type="revolute">
      <origin xyz="0 0.0155 0.0069"
              rpy="0 0 0" />
      <parent link="${parent}" />
      <child link="${prefix}rs1_130_link" />
      <axis xyz="-1 0 0" />
      <limit lower="0"
             upper="0.5"
             effort="10"
             velocity="10" />
      <mimic joint="${mimic_joint}"
             multiplier="51"
             offset="0" />
    </joint>

    <joint name="${prefix}rs1_139_joint"
           type="revolute">
      <origin xyz="0 -0.0155 0.0069"
              rpy="0 0 0" />
      <parent link="${parent}" />
      <child link="${prefix}rs1_139_link" />
      <axis xyz="1 0 0" />
      <limit lower="0"
             upper="0.5"
             effort="10"
             velocity="10" />
      <mimic joint="${prefix}rs1_130_joint"
             multiplier="1"
             offset="0" />
    </joint>

    <joint name="${prefix}tcp_joint"
           type="fixed">
      <origin xyz="0 0 0.04"
              rpy="0 ${-pi / 2} 0" />
      <parent link="${parent}" />
      <child link="${prefix}tcp" />
    </joint>

  </xacro:macro>

</robot>
