<?xml version="1.0"?>
<robot xmlns:xacro="http://ros.org/wiki/xacro">

  <xacro:macro name="alpha_5_urdf"
               params="parent prefix *origin joint_limits_file mount_rotation:=^0">

    <!-- dynamically load the joint limits from a configuration file -->
    <!-- this lets us modify a configuration file instead of requiring the implementation of a new URDF -->
    <xacro:property name="joint_limits_file"
                    default="$(arg joint_limits_file)" />
    <xacro:property name="joint_limits"
                    value="${xacro.load_yaml(joint_limits_file)['joint_limits']}" />

    <!-- links -->
    <!-- the distance from the mount center to the base_link is xyz="0.0374 0 0.0225" -->
    <link name="${prefix}base_link">
      <visual>
        <geometry>
          <mesh filename="file://$(find reach_description)/meshes/alpha_5/RS1-1010.dae" />
        </geometry>
        <origin rpy="${mount_rotation} 0 0"
                xyz="0 0 0" />
      </visual>
      <collision>
        <geometry>
          <cylinder length="0.150"
                    radius="0.020" />
        </geometry>
        <origin rpy="0 1.57075 0"
                xyz="-0.055 0 0" />
      </collision>
      <inertial>
        <mass value="0.0001" />
        <inertia ixx="0.0001"
                 ixy="0"
                 ixz="0"
                 iyy="0.0001"
                 iyz="0"
                 izz="0.0001" />
      </inertial>
    </link>

    <link name="${prefix}m3_inline_link">
      <visual>
        <geometry>
          <mesh filename="file://$(find reach_description)/meshes/alpha_5/M3-INLINE.dae" />
        </geometry>
        <origin rpy="0 0 0"
                xyz="0 0 0" />
      </visual>
      <collision>
        <geometry>
          <cylinder length="0.150"
                    radius="0.020" />
        </geometry>
        <origin rpy="0 1.57075 0"
                xyz="-0.055 0 0" />
      </collision>
      <inertial>
        <mass value="0.341" />
        <origin xyz="-0.055 0 0" />
        <inertia ixx="0.0000682"
                 ixy="0"
                 ixz="0"
                 iyy="0.000673"
                 iyz="0"
                 izz="0.000673" />
      </inertial>
    </link>

    <link name="${prefix}m2_1_1_link">
      <visual>
        <geometry>
          <mesh filename="file://$(find reach_description)/meshes/alpha_5/M2-1-1.dae" />
        </geometry>
        <origin rpy="0 0 0"
                xyz="0 0 0" />
      </visual>
      <collision>
        <geometry>
          <cylinder length="0.033"
                    radius="0.020" />
        </geometry>
        <origin rpy="0 0 0"
                xyz="0 0 0.0165" />
      </collision>
      <inertial>
        <mass value="0.194" />
        <origin xyz="0 0 0.0165" />
        <inertia ixx="0.000037"
                 ixy="0"
                 ixz="0"
                 iyy="0.000037"
                 iyz="0"
                 izz="0.0000388" />
      </inertial>
    </link>

    <link name="${prefix}m2_link">
      <visual>
        <geometry>
          <mesh filename="file://$(find reach_description)/meshes/alpha_5/M2.dae" />
        </geometry>
        <origin rpy="0 0 0"
                xyz="0 0 0" />
      </visual>
      <collision>
        <geometry>
          <cylinder length="0.145"
                    radius="0.020" />
        </geometry>
        <origin rpy="0 0 0"
                xyz="-0.02 0 -0.0725" />
      </collision>
      <collision>
        <geometry>
          <cylinder length="0.040"
                    radius="0.020" />
        </geometry>
        <origin rpy="1.5707 0 0"
                xyz="0 0 0" />
      </collision>
      <collision>
        <geometry>
          <cylinder length="0.040"
                    radius="0.020" />
        </geometry>
        <origin rpy="1.5707 0 0"
                xyz="-0.040 0 -0.1453" />
      </collision>
      <inertial>
        <mass value="0.429" />
        <origin xyz="-0.02 0 -0.0725" />
        <inertia ixx="0.0008907"
                 ixy="0"
                 ixz="0"
                 iyy="0.0008907"
                 iyz="0"
                 izz="0.0000858" />
      </inertial>
    </link>

    <link name="${prefix}m2_1_3_link">
      <visual>
        <geometry>
          <mesh filename="file://$(find reach_description)/meshes/alpha_5/M2-1-3.dae" />
        </geometry>
        <origin rpy="0 0 0"
                xyz="0 0 0" />
      </visual>
      <collision>
        <geometry>
          <cylinder length="0.033"
                    radius="0.020" />
        </geometry>
        <origin rpy="0 0 0"
                xyz="0.02 0 0.0165" />
      </collision>
      <inertial>
        <mass value="0.115" />
        <origin xyz="0.02 0 0.0165" />
        <inertia ixx="0.0000219"
                 ixy="0"
                 ixz="0"
                 iyy="0.0000219"
                 iyz="0"
                 izz="0.000023" />
      </inertial>
    </link>

    <link name="${prefix}m1_link">
      <visual>
        <geometry>
          <mesh filename="file://$(find reach_description)/meshes/alpha_5/M1.dae" />
        </geometry>
        <origin rpy="0 -1.5707 0"
                xyz="0 0 0" />
      </visual>
      <collision>
        <geometry>
          <cylinder length="0.1"
                    radius="0.020" />
        </geometry>
        <origin rpy="0 0 0"
                xyz="0 0 0.05" />
      </collision>
      <inertial>
        <mass value="0.200" />
        <origin xyz="0 0 0.05" />
        <inertia ixx="0.0001867"
                 ixy="0"
                 ixz="0"
                 iyy="0.0001867"
                 iyz="0"
                 izz="0.00004" />
      </inertial>
    </link>

    <link name="${prefix}rs1_124_link">
      <visual>
        <geometry>
          <mesh filename="file://$(find reach_description)/meshes/alpha_5/RS1-124.dae" />
        </geometry>
        <origin rpy="0 -1.5707 0"
                xyz="0 0 0" />
      </visual>
      <collision>
        <geometry>
          <cylinder length="0.1"
                    radius="0.020" />
        </geometry>
        <origin rpy="0 0 0"
                xyz="0 0 0.05" />
      </collision>
      <inertial>
        <mass value="0.0001" />
        <inertia ixx="0.0001"
                 ixy="0"
                 ixz="0"
                 iyy="0.0001"
                 iyz="0"
                 izz="0.0001" />
      </inertial>
    </link>

    <link name="${prefix}push_rod">
      <visual>
        <origin rpy="0 0 0"
                xyz="0 0 0" />
        <geometry>
          <box size="0.001 0.001 0.001" />
        </geometry>
        <material name="transparent">
          <color rgba="0 0 0 0" />
        </material>
      </visual>
      <inertial>
        <mass value="0.0001" />
        <inertia ixx="0.0001"
                 ixy="0"
                 ixz="0"
                 iyy="0.0001"
                 iyz="0"
                 izz="0.0001" />
      </inertial>
    </link>

    <!-- joints -->
    <joint name="${prefix}base_joint"
           type="fixed">
      <xacro:insert_block name="origin" />
      <parent link="${parent}" />
      <child link="${prefix}base_link" />
    </joint>

    <joint name="${prefix}mount_joint"
           type="fixed">
      <parent link="${prefix}base_link" />
      <child link="${prefix}m3_inline_link" />
      <origin xyz="0.124 0.004 0"
              rpy="0 0 0" />
    </joint>

    <joint name="${prefix}axis_e"
           type="revolute">
      <parent link="${prefix}m3_inline_link" />
      <child link="${prefix}m2_1_1_link" />
      <origin xyz="0 0 0.014" />
      <axis xyz="0 0 1" />
      <limit effort="9.0"
             lower="${joint_limits['axis_e']['min_position']}"
             upper="${joint_limits['axis_e']['max_position']}"
             velocity="0.5" />
    </joint>

    <joint name="${prefix}axis_d"
           type="revolute">
      <parent link="${prefix}m2_1_1_link" />
      <child link="${prefix}m2_link" />
      <origin xyz="-0.02 0 0.033" />
      <axis xyz="0 1 0" />
      <limit effort="9.0"
             lower="${joint_limits['axis_d']['min_position']}"
             upper="${joint_limits['axis_d']['max_position']}"
             velocity="0.5" />
    </joint>

    <joint name="${prefix}axis_c"
           type="revolute">
      <parent link="${prefix}m2_link" />
      <child link="${prefix}m2_1_3_link" />
      <origin xyz="-0.04 0 -0.1453"
              rpy="0 0 3.14159" />
      <axis xyz="0 1 0" />
      <limit effort="9.0"
             lower="${joint_limits['axis_c']['min_position']}"
             upper="${joint_limits['axis_c']['max_position']}"
             velocity="0.5" />
    </joint>

    <joint name="${prefix}axis_b"
           type="revolute">
      <parent link="${prefix}m2_1_3_link" />
      <child link="${prefix}m1_link" />
      <origin xyz="0.02 0 0.033"
              rpy="0 0 2.09439" />
      <axis xyz="0 0 -1" />
      <limit effort="9.0"
             lower="${joint_limits['axis_b']['min_position']}"
             upper="${joint_limits['axis_b']['max_position']}"
             velocity="0.5" />
    </joint>

    <joint name="${prefix}tcp_base_joint"
           type="fixed">
      <origin rpy="0 0 0"
              xyz="0 0 0.09975" />
      <parent link="${prefix}m1_link" />
      <child link="${prefix}rs1_124_link" />
    </joint>

    <joint name="${prefix}axis_a"
           type="prismatic">
      <origin rpy="0 0 0"
              xyz="0 0 0.009" />
      <parent link="${prefix}rs1_124_link" />
      <child link="${prefix}push_rod" />
      <axis xyz="0 0 1" />
      <limit effort="10"
             lower="${joint_limits['axis_a']['min_position']}"
             upper="${joint_limits['axis_a']['max_position']}"
             velocity="10" />
    </joint>

  </xacro:macro>

</robot>
